Workbook

Sheet tháng 1
B3: XUẤT HÓA ĐƠN | C3: Ngày | D3: Nội Dung | E3: Tiền | F3: Thuế | G3: Tổng tiền | H3: HÓA ĐƠN ĐẦU VÀO | I3: Ngày | J3: Nội Dung | K3: Tiền | L3: Thuế | M3: Tổng tiền
C4: 45296 | D4: khách lẻ | E4: 1312963 | F4: 105037 | G4: =SUM(E4:F4) -> 1418000 | I4: 45321 | J4: hóa đơn xd new dana | K4: 16805556 | L4: 1344444 | M4: =SUM(K4:L4) -> 18150000
C5: 45303 | D5: tiền phòng 404 | E5: 6912500 | F5: 553000 | G5: =SUM(E5:F5) -> 7465500 | I5: 45321 | J5: ví vimo | K5: 87455 | L5: 8745 | M5: =SUM(K5:L5) -> 96200
C6: 45309 | D6: tiền phòng 801 | E6: 833333 | F6: 66667 | G6: =SUM(E6:F6) -> 900000 | I6: 45303 | J6: nước giặt | K6: 1050000 | L6: 105000 | M6: =SUM(K6:L6) -> 1155000
C7: 45311 | D7: tiền phòng 304 | E7: 8364500 | F7: 669160 | G7: =SUM(E7:F7) -> 9033660 | I7: 45300 | J7: tiền nước | K7: 1232382 | L7: 67734 | M7: =SUM(K7:L7) -> 1300116
C8: 45315 | D8: tiền phòng 601 | E8: 370370 | F8: 29630 | G8: =SUM(E8:F8) -> 400000 | I8: 45322 | J8: tiền wifi | K8: 510455 | L8: 51046 | M8: =SUM(K8:L8) -> 561501
C9: 45317 | D9: khách lẻ | E9: 2777778 | F9: 222222 | G9: =SUM(E9:F9) -> 3000000 | I9: 45295 | J9: viễn thông cmc | K9: 20000 | L9: 2000 | M9: =SUM(K9:L9) -> 22000
C10: 45320 | D10: khách lẻ | E10: 1666667 | F10: 333333 | G10: =SUM(E10:F10) -> 2000000 | I10: 45658 | J10: tiền điện | K10: 9970520 | L10: 797642 | M10: =SUM(K10:L10) -> 10768162
D22: Tổng | E22: =SUM(E4:E21) -> 22238111 | F22: =SUM(F4:F21) -> 1979049 | G22: =SUM(E22:F22) -> 24217160 | K22: =SUM(K4:K21) -> 29676368 | L22: =SUM(L4:L21) -> 2376611 | M22: =SUM(K22:L22) -> 32052979

Sheet tháng 2
B3: XUẤT HÓA ĐƠN | C3: Ngày | D3: Nội Dung | E3: Tiền | F3: Thuế | G3: Tổng tiền | H3: HÓA ĐƠN ĐẦU VÀO | I3: Ngày | J3: Nội Dung | K3: Tiền | L3: Thuế | M3: Tổng tiền
C4: 45329 | D4: tiền phòng 704 | E4: 925926 | F4: 74074 | G4: =SUM(E4:F4) -> 1000000 | I4: 45327 | J4: Nước Dasani | K4: 555556 | L4: 44444 | M4: =SUM(K4:L4) -> 600000
C5: 45336 | D5: tiền phòng 404 | E5: 6886574 | F5: 550926 | G5: =SUM(E5:F5) -> 7437500 | I5: 45323 | J5: Tiền điện | K5: 8285173 | L5: 662814 | M5: =SUM(K5:L5) -> 8947987
C6: 45337 | D6: tiền phòng 801 | E6: 7777778 | F6: 622222 | G6: =SUM(E6:F6) -> 8400000 | I6: 45326 | J6: Viễn thông CMC | K6: 20000 | L6: 2000 | M6: =SUM(K6:L6) -> 22000
C7: 45338 | D7: khách lẻ | E7: 5555556 | F7: 444444 | G7: =SUM(E7:F7) -> 6000000 | I7: 45338 | J7: Tiền nước | K7: 1232382 | L7: 67734 | M7: =SUM(K7:L7) -> 1300116
C8: 45342 | D8: khách lẻ | E8: 1018519 | F8: 81481 | G8: =SUM(E8:F8) -> 1100000 | I8: 45348 | J8: Hóa đơn tiếp khách | K8: 1360000 | L8: 108800 | M8: =SUM(K8:L8) -> 1468800
C9: 45342 | D9: tiền phòng 304 | E9: 8119500 | F9: 649560 | G9: =SUM(E9:F9) -> 8769060 | I9: 45351 | J9: Tiền wifi | K9: 510455 | L9: 51046 | M9: =SUM(K9:L9) -> 561501
I10: 47150 | J10: vimo | K10: 496350 | L10: 49635 | M10: =SUM(K10:L10) -> 545985
D22: Tổng | E22: =SUM(E4:E20) -> 30283853 | F22: =SUM(F4:F21) -> 2422707 | G22: =SUM(G4:G21) -> 32706560 | J22: Tổng | K22: =SUM(K4:K21) -> 12459916 | L22: =SUM(L4:L21) -> 986473 | M22: =SUM(M4:M21) -> 13446389

Sheet tháng 3
B3: XUẤT HÓA ĐƠN | C3: Ngày | D3: Nội Dung | E3: Tiền | F3: Thuế | G3: Tổng tiền | H3: HÓA ĐƠN ĐẦU VÀO | I3: Ngày | J3: Nội Dung | K3: Tiền | L3: Thuế | M3: Tổng tiền
C4: 45352 | D4: Khách lẻ | E4: 555556 | F4: 44444 | G4: =SUM(E4:F4) -> 600000 | I4: 45355 | J4: Viễn Thông CMC | K4: 22869 | L4: 2287 | M4: =SUM(K4:L4) -> 25156
C5: 45357 | D5: Khách lẻ | E5: 2037037 | F5: 162963 | G5: =SUM(E5:F5) -> 2200000 | I5: 45353 | J5: tiền điện | K5: 7678385 | L5: 614271 | M5: =SUM(K5:L5) -> 8292656
C6: 45362 | D6: Hđ Hoàng Văn Dương | E6: 3703704 | F6: 296296 | G6: =SUM(E6:F6) -> 4000000 | I6: 45364 | J6: tiền nước giặt | K6: 920000 | L6: 92000 | M6: =SUM(K6:L6) -> 1012000
C7: 45368 | D7: Khách lẻ | E7: 2777779 | F7: 222221 | G7: =SUM(E7:F7) -> 3000000 | I7: 45360 | J7: tiền nước | K7: 1093739 | L7: 60114 | M7: =SUM(K7:L7) -> 1153853
C8: 45373 | D8: tiền phòng 304 | E8: 8581500 | F8: 686520 | G8: =SUM(E8:F8) -> 9268020 | I8: 45371 | J8: chữ ký số WINCA | K8: 2800000 | L8: 280000 | M8: =SUM(K8:L8) -> 3080000
C9: 45377 | D9: tiền phòng 701 | E9: 416667 | F9: 33333 | G9: =SUM(E9:F9) -> 450000 | I9: 45376 | J9: hóa đơn xd NEW DANA | K9: 10694444 | L9: 855556 | M9: =SUM(K9:L9) -> 11550000
C10: 45377 | D10: tiền phòng 504 | E10: 648148 | F10: 51852 | G10: =SUM(E10:F10) -> 700000 | I10: 45378 | J10: hóa đơn tiếp khách | K10: 2054000 | L10: 164320 | M10: =SUM(K10:L10) -> 2218320
C11: 45377 | D11: khách lẻ phòng 402 | E11: 2500000 | F11: 200000 | G11: =SUM(E11:F11) -> 2700000 | I11: 45381 | J11: hóa đơn tiếp khách 2 | K11: 1447660 | L11: 123340 | M11: =SUM(K11:L11) -> 1571000
C12: 45378 | D12: tiền phòng 404 | E12: 1111111 | F12: 88889 | G12: =SUM(E12:F12) -> 1200000 | I12: 45381 | J12: Ví vimo | K12: 40694 | L12: 4069 | M12: =SUM(K12:L12) -> 44763
C13: 45381 | D13: khách lẻ 404 , 504 | E13: 1018518 | F13: 81482 | G13: =SUM(E13:F13) -> 1100000 | I13: 45382 | J13: tiền wifi | K13: 510455 | L13: 51046 | M13: =SUM(K13:L13) -> 561501
C14: 45382 | D14: khách lẻ 702 | E14: 277778 | F14: 22222 | G14: =SUM(E14:F14) -> 300000
D22: Tổng | E22: =SUM(E4:E20) -> 23627798 | F22: =SUM(F4:F21) -> 1890222 | G22: =SUM(G4:G21) -> 25518020 | J22: Tổng | K22: =SUM(K4:K21) -> 27262246 | L22: =SUM(L4:L21) -> 2247003 | M22: =SUM(M4:M21) -> 29509249

Sheet tháng 4
B3: XUẤT HÓA ĐƠN | C3: Ngày | D3: Nội Dung | E3: Tiền | F3: Thuế | G3: Tổng tiền | H3: HÓA ĐƠN ĐẦU VÀO | I3: Ngày | J3: Nội Dung | K3: Tiền | L3: Thuế | M3: Tổng tiền
C4: 45386 | D4: khách lẻ 504 | E4: 509259 | F4: 40741 | G4: =SUM(E4:F4) -> 550000 | I4: 45383 | J4: tiền điện | K4: 11062863 | L4: 885029 | M4: =SUM(K4:L4) -> 11947892
C5: 45392 | D5: Khách lẻ 302 | E5: 1388889 | F5: 111111 | G5: =SUM(E5:F5) -> 1500000 | I5: 45386 | J5: Viễn thông CMC | K5: 20000 | L5: 2000 | M5: =SUM(K5:L5) -> 22000
C6: 45396 | D6: khách lẻ 802 | E6: 6944444 | F6: 555556 | G6: =SUM(E6:F6) -> 7500000 | I6: 45389 | J6: hóa đơn tiếp khách | K6: 420000 | L6: 42000 | M6: =SUM(K6:L6) -> 462000
C7: 45402 | D7: khách lẻ | E7: 2685185 | F7: 214815 | G7: =SUM(E7:F7) -> 2900000 | I7: 45389 | J7: hóa đơn tiếp khách | K7: 2289000 | L7: 183120 | M7: =SUM(K7:L7) -> 2472120
C8: 45402 | D8: khách lẻ | E8: 555556 | F8: 44444 | G8: =SUM(E8:F8) -> 600000 | I8: 45391 | J8: hóa đơn tiếp khách 2 | K8: 2462963 | L8: 197037 | M8: =SUM(K8:L8) -> 2660000
C9: 45403 | D9: phòng 304 | E9: 8872000 | F9: 709760 | G9: =SUM(E9:F9) -> 9581760 | I9: 45391 | J9: tiền nước | K9: 1386430 | L9: 76200 | M9: =SUM(K9:L9) -> 1462630
C10: 45412 | D10: khách lẻ | E10: 4722221 | F10: 377779 | G10: =SUM(E10:F10) -> 5100000 | I10: 45387 | J10: thu gom rác | K10: 240909 | L10: 19273 | M10: =SUM(K10:L10) -> 260182
C11: 45412 | D11: khách lẻ | E11: 2222220 | F11: 177780 | G11: =SUM(E11:F11) -> 2400000 | I11: 45411 | J11: vií vimo | K11: 89742 | L11: 8974 | M11: =SUM(K11:L11) -> 98716
C12: 45412 | D12: khách lẻ | E12: 5555557 | F12: 444443 | G12: =SUM(E12:F12) -> 6000000 | I12: 45411 | J12: lõi lọc nước | K12: 731481 | L12: 58519 | M12: =SUM(K12:L12) -> 790000
I13: 45409 | J13: nước suối | K13: 902778 | L13: 72222 | M13: =SUM(K13:L13) -> 975000
I14: 45412 | J14: tiền wifi | K14: 510455 | L14: 51046 | M14: =SUM(K14:L14) -> 561501
D22: Tổng | E22: =SUM(E4:E20) -> 33455331 | F22: =SUM(F4:F21) -> 2676429 | G22: =SUM(G4:G21) -> 36131760 | J22: Tổng | K22: =SUM(K4:K21) -> 20116621 | L22: =SUM(L4:L21) -> 1595420 | M22: =SUM(M4:M21) -> 21712041

Sheet tháng 5
B3: XUẤT HÓA ĐƠN | C3: Ngày | D3: Nội Dung | E3: Tiền | F3: Thuế | G3: Tổng tiền | H3: HÓA ĐƠN ĐẦU VÀO | I3: Ngày | J3: Nội Dung | K3: Tiền | L3: Thuế | M3: Tổng tiền
C4: 45419 | D4: khách Đình Quang p503,504 | E4: 925926 | F4: 74074 | G4: =SUM(E4:F4) -> 1000000 | I4: 45414 | J4: thiết bị wifi | K4: 2400000 | L4: 240000 | M4: =SUM(K4:L4) -> 2640000
C5: 45432 | D5: tiền phòng 304 | E5: 9281500 | F5: 742520 | G5: =SUM(E5:F5) -> 10024020 | I5: 45415 | J5: tiền điện | K5: 14621225 | L5: 1169698 | M5: =SUM(K5:L5) -> 15790923
C6: 45432 | D6: khách lẻ | E6: 1388889 | F6: 111111 | G6: =SUM(E6:F6) -> 1500000 | I6: 45416 | J6: viễn thông cmc | K6: 26537 | L6: 2654 | M6: =SUM(K6:L6) -> 29191
C7: 45434 | D7: khách Đức Hạnh 301 | E7: 833333 | F7: 66667 | G7: =SUM(E7:F7) -> 900000 | I7: 45418 | J7: tiền rác | K7: 240909 | L7: 19273 | M7: =SUM(K7:L7) -> 260182
C8: 45436 | D8: Khách 802 | E8: 6944444 | F8: 555556 | G8: =SUM(E8:F8) -> 7500000 | I8: 45427 | J8: hóa đơn tiếp khách | K8: 1130760 | L8: 33000 | M8: =SUM(K8:L8) -> 1163760
C9: 45437 | D9: Khách Ali Roshandel 602 | E9: 2314815 | F9: 185185 | G9: =SUM(E9:F9) -> 2500000 | I9: 45427 | J9: thép vật liệu | K9: 4547500 | L9: 454750 | M9: =SUM(K9:L9) -> 5002250
I10: 45430 | J10: văn phòng phẩm | K10: 330500 | L10: 26690 | M10: =SUM(K10:L10) -> 357190
I11: 45428 | J11: hóa đơn tiếp khách 2 | K11: 2092000 | L11: 167360 | M11: =SUM(K11:L11) -> 2259360
I12: 45434 | J12: vật liệu sửa chữa | K12: 833333 | L12: 66667 | M12: =SUM(K12:L12) -> 900000
I13: 45434 | J13: vật liệu sửa chữa | K13: 636364 | L13: 63636 | M13: =SUM(K13:L13) -> 700000
I14: 45432 | J14: nước giặt | K14: 2118000 | L14: 211800 | M14: =SUM(K14:L14) -> 2329800
I15: 45443 | J15: Vií vimo | K15: 115265 | L15: 11527 | M15: =SUM(K15:L15) -> 126792
I16: 45421 | J16: tiền nước | K16: 1586692 | L16: 87206 | M16: =SUM(K16:L16) -> 1673898
I17: 45443 | J17: tiền wifi | K17: 510455 | L17: 51046 | M17: =SUM(K17:L17) -> 561501
D22: Tổng | E22: =SUM(E4:E20) -> 21688907 | F22: =SUM(F4:F21) -> 1735113 | G22: =SUM(G4:G21) -> 23424020 | J22: Tổng | K22: =SUM(K4:K21) -> 31189540 | L22: =SUM(L4:L21) -> 2605307 | M22: =SUM(M4:M21) -> 33794847

Sheet tháng 6
B3: XUẤT HÓA ĐƠN | C3: Ngày | D3: Nội Dung | E3: Tiền | F3: Thuế | G3: Tổng tiền | H3: HÓA ĐƠN ĐẦU VÀO | I3: Ngày | J3: Nội Dung | K3: Tiền | L3: Thuế | M3: Tổng tiền
C4: 45450 | D4: khách lẻ Kim Namjomh 602 | E4: 555556 | F4: 44444 | G4: =SUM(E4:F4) -> 600000 | I4: 45446 | J4: Hóa đơn xd NEW DANA | K4: 13500000 | L4: 1080000 | M4: =SUM(K4:L4) -> 14580000
C5: 45455 | D5: khách lẻ | E5: 8055555 | F5: 644445 | G5: =SUM(E5:F5) -> 8700000 | I5: 45447 | J5: viễn thông CMC | K5: 22620 | L5: 2262 | M5: =SUM(K5:L5) -> 24882
C6: 45455 | D6: khách lẻ | E6: 1388889 | F6: 111111 | G6: =SUM(E6:F6) -> 1500000 | I6: 45445 | J6: tiền điện | K6: 11188821 | L6: 895106 | M6: =SUM(K6:L6) -> 12083927
C7: 45455 | D7: khách lẻ | E7: 7037038 | F7: 562962 | G7: =SUM(E7:F7) -> 7600000 | I7: 45448 | J7: tiền rác | K7: 240909 | L7: 19273 | M7: =SUM(K7:L7) -> 260182
C8: 45459 | D8: khách lẻ | E8: 9722220 | F8: 777780 | G8: =SUM(E8:F8) -> 10500000 | I8: 45451 | J8: tiền nước | K8: 1309406 | L8: 71967 | M8: =SUM(K8:L8) -> 1381373
C9: 45460 | D9: tnhh smart | E9: 740741 | F9: 59259 | G9: =SUM(E9:F9) -> 800000 | I9: 45468 | J9: hóa đơn tiếp khách | K9: 215454 | L9: 21545 | M9: =SUM(K9:L9) -> 236999
C10: 45460 | D10: khách lẻ | E10: 1296296 | F10: 103704 | G10: =SUM(E10:F10) -> 1400000 | I10: 45468 | J10: hóa đơn tiếp khách 2 | K10: 3089815 | L10: 247185 | M10: =SUM(K10:L10) -> 3337000
C11: 45463 | D11: khách 304 | E11: 9932500 | F11: 794600 | G11: =SUM(E11:F11) -> 10727100 | I11: 45468 | J11: hóa đơn tiếp khách 3 | K11: 4345000 | L11: 358400 | M11: =SUM(K11:L11) -> 4703400
C12: 45466 | D12: khách lẻ 702 | E12: 370370 | F12: 29630 | G12: =SUM(E12:F12) -> 400000 | I12: 45472 | J12: dasani | K12: 1300000 | L12: 104000 | M12: =SUM(K12:L12) -> 1404000
C13: 45466 | D13: khách lẻ 602 | E13: 1111111 | F13: 88889 | G13: =SUM(E13:F13) -> 1200000 | I13: 45472 | J13: vií vimo | K13: 31182 | L13: 3118 | M13: =SUM(K13:L13) -> 34300
C14: 45466 | D14: khách lẻ | E14: 9444442 | F14: 755558 | G14: =SUM(E14:F14) -> 10200000 | I14: 45473 | J14: tiền wifi | K14: 510455 | L14: 51046 | M14: =SUM(K14:L14) -> 561501
C15: 45467 | D15: khách lẻ 801 | E15: 3935185 | F15: 314815 | G15: =SUM(E15:F15) -> 4250000 | M15: =SUM(K15:L15) -> 0
C16: 45467 | D16: khách lẻ | E16: 8518519 | F16: 681481 | G16: =SUM(E16:F16) -> 9200000
C17: 45470 | D17: khách lẻ | E17: 833333 | F17: 66667 | G17: =SUM(E17:F17) -> 900000
C18: 45473 | D18: khách lẻ 704 | E18: 1481482 | F18: 118519 | G18: =SUM(E18:F18) -> 1600001
C19: 45473 | D19: khách lẻ | E19: 740740 | F19: 59260 | G19: =SUM(E19:F19) -> 800000
C20: 45473 | D20: khách lẻ | E20: 7037036 | F20: 562964 | G20: =SUM(E20:F20) -> 7600000
D22: Tổng | E22: =SUM(E4:E20) -> 72201013 | F22: =SUM(F4:F21) -> 5776088 | G22: =SUM(G4:G21) -> 77977101 | J22: Tổng | K22: =SUM(K4:K21) -> 35753662 | L22: =SUM(L4:L21) -> 2853902 | M22: =SUM(M4:M21) -> 38607564
E31: ='tháng 6'!E22+'tháng 5'!E22+'tháng 4'!E22 -> 127345251 | F31: ='tháng 6'!F22+'tháng 5'!F22+'tháng 4'!F22 -> 10187630 | G31: ='tháng 6'!G22+'tháng 5'!G22+'tháng 4'!G22 -> 137532881 | K31: =K22+'tháng 5'!K22+'tháng 4'!K22 -> 87059823 | L31: =L22+'tháng 5'!L22+'tháng 4'!L22 -> 7054629 | M31: =M22+'tháng 5'!M22+'tháng 4'!M22 -> 94114452

Sheet tháng 7
B3: XUẤT HÓA ĐƠN | C3: Ngày | D3: Nội Dung | E3: Tiền | F3: Thuế | G3: Tổng tiền | H3: HÓA ĐƠN ĐẦU VÀO | I3: Ngày | J3: Nội Dung | K3: Tiền | L3: Thuế | M3: Tổng tiền
C4: 45475 | D4: Khách lẻ 302 | E4: 636364 | F4: 63636 | G4: =SUM(E4:F4) -> 700000 | I4: 45477 | J4: CMC viễn thông | K4: 24481 | L4: 2448 | M4: =SUM(K4:L4) -> 26929
C5: 45478 | D5: khách lẻ 701 | E5: 462963 | F5: 37037 | G5: =SUM(E5:F5) -> 500000 | I5: 45476 | J5: tiền điện | K5: 19634504 | L5: 1570724 | M5: =SUM(K5:L5) -> 21205228
C6: 45479 | D6: khách lẻ 704 | E6: 1203704 | F6: 96296 | G6: =SUM(E6:F6) -> 1300000 | I6: 45484 | J6: dasani | K6: 972222 | L6: 77778 | M6: =SUM(K6:L6) -> 1050000
C7: 45481 | D7: khách lẻ | E7: 1851852 | F7: 148148 | G7: =SUM(E7:F7) -> 2000000 | I7: 45483 | J7: sửa điện thoại bàn | K7: 1000000 | L7: 100000 | M7: =SUM(K7:L7) -> 1100000
C8: 45481 | D8: khách lẻ | E8: 2222222 | F8: 177778 | G8: =SUM(E8:F8) -> 2400000 | I8: 45482 | J8: tiền nước | K8: 2048836 | L8: 112607 | M8: =SUM(K8:L8) -> 2161443
C9: 45482 | D9: khách lẻ 604,704 | E9: 2962964 | F9: 237038 | G9: =SUM(E9:F9) -> 3200002 | I9: 45502 | J9: tăm bông, lược | K9: 750000 | L9: 60000 | M9: =SUM(K9:L9) -> 810000
C10: 45488 | D10: khách lẻ Trang Nguyen | E10: 3333332 | F10: 266668 | G10: =SUM(E10:F10) -> 3600000 | I10: 45502 | J10: bộ bàn chải | K10: 1440000 | L10: 144000 | M10: =SUM(K10:L10) -> 1584000
C11: 45488 | D11: khách lẻ | E11: 10000000 | F11: 800000 | G11: =SUM(E11:F11) -> 10800000 | I11: 45502 | J11: nước giặt | K11: 1096363 | L11: 109636 | M11: =SUM(K11:L11) -> 1205999
C12: 45488 | D12: khách lẻ | E12: 15648148 | F12: 1251853 | G12: =SUM(E12:F12) -> 16900001 | I12: 45482 | J12: tiền rác | K12: 240909 | L12: 19273 | M12: =SUM(K12:L12) -> 260182
C13: 45493 | D13: khách lẻ 301 | E13: 462963 | F13: 37037 | G13: =SUM(E13:F13) -> 500000 | I13: 45504 | J13: ví vimo | K13: 155166 | L13: 15517 | M13: =SUM(K13:L13) -> 170683
C14: 45493 | D14: tiền phòng 304 | E14: 8998000 | F14: 719840 | G14: =SUM(E14:F14) -> 9717840 | I14: 45504 | J14: tiền wifi | K14: 510455 | L14: 51046 | M14: =SUM(K14:L14) -> 561501
C15: 45493 | D15: khách lẻ Ngoc Huyen | E15: 2663889 | F15: 213111 | G15: =SUM(E15:F15) -> 2877000 | M15: =SUM(K15:L15) -> 0
C16: 45497 | D16: khách lẻ | E16: 6851851 | F16: 548149 | G16: =SUM(E16:F16) -> 7400000
C17: 45497 | D17: khách lẻ | E17: 2592593 | F17: 207407 | G17: =SUM(E17:F17) -> 2800000
C18: 45497 | D18: khách lẻ 801 | E18: 1944444 | F18: 155556 | G18: =SUM(E18:F18) -> 2100000
C19: 45498 | D19: khách lẻ 602 | E19: 1111111 | F19: 88889 | G19: =SUM(E19:F19) -> 1200000
C20: 45499 | D20: khách lẻ 401,402 | E20: 1018519 | F20: 81481 | G20: =SUM(E20:F20) -> 1100000
C21: 45499 | D21: khách lẻ 302 | E21: 925926 | F21: 74074 | G21: =SUM(E21:F21) -> 1000000
C22: 45503 | D22: khách lẻ Thai Hien, Shu Ying | E22: 4259259 | F22: 340741 | G22: =SUM(E22:F22) -> 4600000
C23: 45503 | D23: Khách lẻ 702,703 | E23: 1666667 | F23: 133333 | G23: =SUM(E23:F23) -> 1800000
D27: Tổng | E27: =SUM(E4:E26) -> 70816771 | F27: =SUM(F4:F26) -> 5678072 | G27: =SUM(G4:G26) -> 76494843 | J27: Tổng | K27: =SUM(K4:K26) -> 27872936 | L27: =SUM(L4:L26) -> 2263029 | M27: =SUM(M4:M26) -> 30135965

Sheet tháng 8
B3: XUẤT HÓA ĐƠN | C3: Ngày | D3: Nội Dung | E3: Tiền | F3: Thuế | G3: Tổng tiền | H3: HÓA ĐƠN ĐẦU VÀO | I3: Ngày | J3: Nội Dung | K3: Tiền | L3: Thuế | M3: Tổng tiền
C4: 45508 | D4: tiền phòng 604 | E4: 7870370 | F4: 629630 | G4: =SUM(E4,F4) -> 8500000 | I4: 45505 | J4: Hóa đơn tiếp khách 1 | K4: 1876000 | L4: 150080 | M4: =SUM(K4,L4) -> 2026080
C5: 45513 | D5: phòng 504 Ngọc Ngũ | E5: 601852 | F5: 48148 | G5: =SUM(E5,F5) -> 650000 | I5: 45505 | J5: Hóa đơn tiếp khách 2 | K5: 2198000 | L5: 175840 | M5: =SUM(K5,L5) -> 2373840
C6: 45517 | D6: 801 ngày 6/8 -10/8 | E6: 2592593 | F6: 207407 | G6: =SUM(E6,F6) -> 2800000 | I6: 45509 | J6: Hóa đơn tiếp khách 3 | K6: 1794000 | L6: 143520 | M6: =SUM(K6,L6) -> 1937520
C7: 45520 | D7: 901 | E7: 1666667 | F7: 133333 | G7: =SUM(E7,F7) -> 1800000 | I7: 45511 | J7: Winpos 3Y | K7: 2880000 | L7: 288000 | M7: =SUM(K7,L7) -> 3168000
C8: 45522 | D8: 302 | E8: 2222222 | F8: 177778 | G8: =SUM(E8,F8) -> 2400000 | I8: 45510 | J8: Dasani | K8: 324074 | L8: 25926 | M8: =SUM(K8,L8) -> 350000
C9: 45524 | D9: tiền phòng 304 | E9: 9834500 | F9: 786760 | G9: =SUM(E9,F9) -> 10621260 | I9: 45506 | J9: tiền điện | K9: 17407255 | L9: 1392580 | M9: =SUM(K9,L9) -> 18799835
C10: 45530 | D10: khách lẻ 602 | E10: 833333 | F10: 66667 | G10: =SUM(E10,F10) -> 900000 | I10: 45513 | J10: tiền nước | K10: 1941002 | L10: 106680 | M10: =SUM(K10,L10) -> 2047682
C11: 45531 | D11: khách lẻ 302,502,702 | E11: 4800000 | F11: 384000 | G11: =SUM(E11,F11) -> 5184000 | I11: 45516 | J11: tiền rác | K11: 240909 | L11: 19273 | M11: =SUM(K11,L11) -> 260182
I12: 45508 | J12: cmc | K12: 23509 | L12: 2351 | M12: =SUM(K12,L12) -> 25860
I13: 45534 | J13: Dasani 2 | K13: 1231482 | L13: 98518 | M13: =SUM(K13,L13) -> 1330000
I14: 45534 | J14: ví vimo | K14: 57818 | L14: 5782 | M14: =SUM(K14,L14) -> 63600
I15: 45535 | J15: tiền wifi | K15: 510455 | L15: 51046 | M15: =SUM(K15,L15) -> 561501
D27: Tổng | E27: =SUM(E4:E26) -> 30421537 | F27: =SUM(F4:F26) -> 2433723 | G27: =SUM(G4:G26) -> 32855260 | J27: Tổng | K27: =SUM(K4:K26) -> 30484504 | L27: =SUM(L4:L26) -> 2459596 | M27: =SUM(M4:M26) -> 32944100

Sheet tháng 9
B3: XUẤT HÓA ĐƠN | C3: Ngày | D3: Nội Dung | E3: Tiền | F3: Thuế | G3: Tổng tiền | H3: HÓA ĐƠN ĐẦU VÀO | I3: Ngày | J3: Nội Dung | K3: Tiền | L3: Thuế | M3: Tổng tiền
C4: 45542 | D4: khách lẻ 702 Hsu | E4: 833333 | F4: 66667 | G4: =SUM(E4,F4) -> 900000 | I4: 45539 | J4: CMC viễn thông | K4: 23891 | L4: 2389 | M4: =SUM(K4,L4) -> 26280
C5: 45545 | D5: khách lẻ 604 | E5: 7870370 | F5: 629630 | G5: =SUM(E5,F5) -> 8500000 | I5: 45548 | J5: Hóa đơn tiếp khách | K5: 7951037 | L5: 636083 | M5: =SUM(K5,L5) -> 8587120
C6: 45555 | D6: tiền phòng 304 | E6: 9068000 | F6: 725440 | G6: =SUM(E6,F6) -> 9793440 | I6: 45544 | J6: tiền nước | K6: 1478858 | L6: 81280 | M6: =SUM(K6,L6) -> 1560138
C7: 45565 | D7: khách lẻ 501 | E7: 740741 | F7: 59259 | G7: =SUM(E7,F7) -> 800000 | I7: 45537 | J7: tiền điện | K7: 13209439 | L7: 1056755 | M7: =SUM(K7,L7) -> 14266194
G8: =SUM(E8,F8) -> 0 | I8: 45555 | J8: tiền sơn | K8: 3900000 | L8: 390000 | M8: =SUM(K8,L8) -> 4290000
G9: =SUM(E9,F9) -> 0 | I9: 45540 | J9: tiền rác | K9: 240909 | L9: 19273 | M9: =SUM(K9,L9) -> 260182
G10: =SUM(E10,F10) -> 0 | I10: 45558 | J10: sửa bồn nước | K10: 1335186 | L10: 106815 | M10: =SUM(K10,L10) -> 1442001
G11: =SUM(E11,F11) -> 0 | I11: 45565 | J11: vimo | K11: 109102 | L11: 10910 | M11: =SUM(K11,L11) -> 120012
I12: 45563 | J12: hóa đơn tiếp khách 2 | K12: 2024000 | L12: 161920 | M12: =SUM(K12,L12) -> 2185920
I13: 45565 | J13: tiền wifi | K13: 510455 | L13: 51046 | M13: =SUM(K13,L13) -> 561501
M14: =SUM(K14,L14) -> 0
D27: Tổng | E27: =SUM(E4:E26) -> 18512444 | F27: =SUM(F4:F26) -> 1480996 | G27: =SUM(G4:G26) -> 19993440 | J27: Tổng | K27: =SUM(K4:K26) -> 30782877 | L27: =SUM(L4:L26) -> 2516471 | M27: =SUM(M4:M26) -> 33299348

Sheet tháng 10
B3: XUẤT HÓA ĐƠN | C3: Ngày | D3: Nội Dung | E3: Tiền | F3: Thuế | G3: Tổng tiền | H3: HÓA ĐƠN ĐẦU VÀO | I3: Ngày | J3: Nội Dung | K3: Tiền | L3: Thuế | M3: Tổng tiền
C4: 45569 | D4: tiền phòng khách Hữu Tuệ | E4: 370370 | F4: 29630 | G4: =SUM(E4:F4) -> 400000 | I4: 45567 | J4: tiền điện | K4: 9396470 | L4: 751718 | M4: =SUM(K4:L4) -> 10148188
C5: 45574 | D5: tiền phòng khách Fahad ali | E5: 277778 | F5: 22222 | G5: =SUM(E5:F5) -> 300000 | I5: 45569 | J5: CMC | K5: 20341 | L5: 2034 | M5: =SUM(K5:L5) -> 22375
C6: 45574 | D6: tiền phòng 504 Vitalii | E6: 6481481 | F6: 518519 | G6: =SUM(E6:F6) -> 7000000 | I6: 45571 | J6: hóa đơn tiếp khách | K6: 4963000 | L6: 397040 | M6: =SUM(K6:L6) -> 5360040
C7: 45579 | D7: tiền phòng 404 Ko sumin | E7: 6018519 | F7: 481481 | G7: =SUM(E7:F7) -> 6500000 | I7: 45574 | J7: hóa đơn tiếp khách 2 | K7: 2199000 | L7: 176520 | M7: =SUM(K7:L7) -> 2375520
C8: 45579 | D8: tiền phòng 704 Kim Huynsik | E8: 6481481 | F8: 518519 | G8: =SUM(E8:F8) -> 7000000 | I8: 45574 | J8: phần mềm wintech | K8: 500000 | L8: 50000 | M8: =SUM(K8:L8) -> 550000
C9: 45585 | D9: tiền phòng 702 | E9: 1666667 | F9: 133333 | G9: =SUM(E9:F9) -> 1800000 | I9: 45575 | J9: tiền nước | K9: 2156669 | L9: 118534 | M9: =SUM(K9:L9) -> 2275203
C10: 45585 | D10: tiền phòng 304 | E10: 8830000 | F10: 706400 | G10: =SUM(E10:F10) -> 9536400 | I10: 45569 | J10: tiền rác | K10: 240909 | L10: 19273 | M10: =SUM(K10:L10) -> 260182
C11: 45588 | D11: tiền phòng 501 Phusa | E11: 1111111 | F11: 88889 | G11: =SUM(E11:F11) -> 1200000 | I11: 45596 | J11: ví vimo | K11: 384159 | L11: 38416 | M11: =SUM(K11:L11) -> 422575
C12: 45591 | D12: tiền phòng 801 Văn Danh | E12: 740741 | F12: 59259 | G12: =SUM(E12:F12) -> 800000 | I12: 45596 | J12: tiền wifi | K12: 510455 | L12: 51046 | M12: =SUM(K12:L12) -> 561501
C13: 45591 | D13: tiền phòng 901 Văn Danh | E13: 740741 | F13: 59259 | G13: =SUM(E13:F13) -> 800000 | I13: 45934 | J13: hóa đơn tiếp khách 3 | K13: 4353720 | M13: =SUM(K13:L13) -> 4353720
C14: 45591 | D14: tiền phòng 502 hsu | E14: 833333 | F14: 66667 | G14: =SUM(E14:F14) -> 900000 | M14: =SUM(K14:L14) -> 0
C15: 45593 | D15: tiền phòng 602 dongku | E15: 833333 | F15: 66667 | G15: =SUM(E15:F15) -> 900000 | M15: =SUM(K15:L15) -> 0
G16: =SUM(E16:F16) -> 0 | M16: =SUM(K16:L16) -> 0
G17: =SUM(E17:F17) -> 0 | M17: =SUM(K17:L17) -> 0
G18: =SUM(E18:F18) -> 0 | M18: =SUM(K18:L18) -> 0
G19: =SUM(E19:F19) -> 0 | M19: =SUM(K19:L19) -> 0
G20: =SUM(E20:F20) -> 0 | M20: =SUM(K20:L20) -> 0
G21: =SUM(E21:F21) -> 0
D27: Tổng | E27: =SUM(E4:E26) -> 34385555 | F27: =SUM(F4:F26) -> 2750845 | G27: =SUM(G4:G26) -> 37136400 | J27: Tổng | K27: =SUM(K4:K26) -> 24724723 | L27: =SUM(L4:L26) -> 1604581 | M27: =SUM(M4:M26) -> 26329304

Sheet tháng 11
B3: XUẤT HÓA ĐƠN | C3: Ngày | D3: Nội Dung | E3: Tiền | F3: Thuế | G3: Tổng tiền | H3: HÓA ĐƠN ĐẦU VÀO | I3: Ngày | J3: Nội Dung | K3: Tiền | L3: Thuế | M3: Tổng tiền
C4: 45603 | D4: tiền phòng 704 kim hyunsik | E4: 6481481 | F4: 518519 | G4: =SUM(E4:F4) -> 7000000 | I4: 45599 | J4: tiền điện | K4: 10673058 | L4: 853845 | M4: =SUM(K4:L4) -> 11526903
C5: 45616 | D5: tiền phòng 304 | E5: 8623500 | F5: 689880 | G5: =SUM(E5:F5) -> 9313380 | I5: 45600 | J5: CMC | K5: 21084 | L5: 2108 | M5: =SUM(K5:L5) -> 23192
G6: =SUM(E6:F6) -> 0 | I6: 45600 | J6: Tiền rác | K6: 240909 | L6: 19273 | M6: =SUM(K6:L6) -> 260182
G7: =SUM(E7:F7) -> 0 | I7: 45611 | J7: hóa đơn tiếp khách | K7: 1263000 | L7: 101040 | M7: =SUM(K7:L7) -> 1364040
G8: =SUM(E8:F8) -> 0 | I8: 45615 | J8: hóa đơn tiếp khách 2 | K8: 2574460 | M8: =SUM(K8:L8) -> 2574460
G9: =SUM(E9:F9) -> 0 | I9: 45616 | J9: bảo hiểm cháy nổ | K9: 9000000 | L9: 900000 | M9: =SUM(K9:L9) -> 9900000
G10: =SUM(E10:F10) -> 0 | I10: 45618 | J10: nước giặt | K10: 518000 | L10: 51800 | M10: =SUM(K10:L10) -> 569800
G11: =SUM(E11:F11) -> 0 | I11: 45605 | J11: tiền nước | K11: 1971812 | L11: 108373 | M11: =SUM(K11:L11) -> 2080185
G12: =SUM(E12:F12) -> 0 | I12: 45626 | J12: ví vimo | K12: 140125 | L12: 14013 | M12: =SUM(K12:L12) -> 154138
G13: =SUM(E13:F13) -> 0 | I13: 45626 | J13: tiền wifi | K13: 510455 | L13: 51046 | M13: =SUM(K13:L13) -> 561501
G14: =SUM(E14:F14) -> 0 | M14: =SUM(K14:L14) -> 0
G15: =SUM(E15:F15) -> 0 | M15: =SUM(K15:L15) -> 0
G16: =SUM(E16:F16) -> 0 | M16: =SUM(K16:L16) -> 0
G17: =SUM(E17:F17) -> 0 | M17: =SUM(K17:L17) -> 0
G18: =SUM(E18:F18) -> 0 | M18: =SUM(K18:L18) -> 0
G19: =SUM(E19:F19) -> 0 | M19: =SUM(K19:L19) -> 0
G20: =SUM(E20:F20) -> 0 | M20: =SUM(K20:L20) -> 0
G21: =SUM(E21:F21) -> 0
D27: Tổng | E27: =SUM(E4:E26) -> 15104981 | F27: =SUM(F4:F26) -> 1208399 | G27: =SUM(G4:G26) -> 16313380 | J27: Tổng | K27: =SUM(K4:K26) -> 26912903 | L27: =SUM(L4:L26) -> 2101498 | M27: =SUM(M4:M26) -> 29014401

Sheet tháng 12
B3: XUẤT HÓA ĐƠN | C3: Ngày | D3: Nội Dung | E3: Tiền | F3: Thuế | G3: Tổng tiền | H3: HÓA ĐƠN ĐẦU VÀO | I3: Ngày | J3: Nội Dung | K3: Tiền | L3: Thuế | M3: Tổng tiền
C4: 45631 | D4: phòng 501 - quang thu | E4: 370370 | F4: 29630 | G4: =SUM(E4:F4) -> 400000 | I4: 45628 | J4: tiền điện | K4: 7589612 | L4: 607169 | M4: =SUM(K4:L4) -> 8196781
C5: 45635 | D5: tiền phòng 704 kim hyunsik | E5: 6481481 | F5: 518519 | G5: =SUM(E5:F5) -> 7000000 | I5: 45630 | J5: cmc | K5: 20667 | L5: 2067 | M5: =SUM(K5:L5) -> 22734
C6: 45640 | D6: tiền phòng 701,703 Shinde | E6: 740740 | F6: 59260 | G6: =SUM(E6:F6) -> 800000 | I6: 45628 | J6: chống mối | K6: 1527778 | L6: 122222 | M6: =SUM(K6:L6) -> 1650000
C7: 45644 | D7: tiền phòng 502 Siti | E7: 555556 | F7: 44444 | G7: =SUM(E7:F7) -> 600000 | I7: 45630 | J7: tiền rác | K7: 240909 | L7: 19273 | M7: =SUM(K7:L7) -> 260182
C8: 45646 | D8: tiền phòng 304 | E8: 3221000 | F8: 257680 | G8: =SUM(E8:F8) -> 3478680 | I8: 45638 | J8: tiền nước | K8: 770239 | L8: 42333 | M8: =SUM(K8:L8) -> 812572
C9: 45647 | D9: tiền phòng 404 Ko Sumin | E9: 6018519 | F9: 481481 | G9: =SUM(E9:F9) -> 6500000 | I9: 46022 | J9: tiền wifi | K9: 510455 | L9: 51046 | M9: =SUM(K9:L9) -> 561501
C10: 45647 | D10: tiền phòng 504 Alena | E10: 6481481 | F10: 518519 | G10: =SUM(E10:F10) -> 7000000 | I10: 46022 | J10: vimo | K10: 99182 | L10: 9918 | M10: =SUM(K10:L10) -> 109100
G11: =SUM(E11:F11) -> 0 | M11: =SUM(K11:L11) -> 0
G12: =SUM(E12:F12) -> 0 | M12: =SUM(K12:L12) -> 0
G13: =SUM(E13:F13) -> 0 | M13: =SUM(K13:L13) -> 0
G14: =SUM(E14:F14) -> 0 | M14: =SUM(K14:L14) -> 0
G15: =SUM(E15:F15) -> 0 | M15: =SUM(K15:L15) -> 0
G16: =SUM(E16:F16) -> 0 | M16: =SUM(K16:L16) -> 0
G17: =SUM(E17:F17) -> 0 | M17: =SUM(K17:L17) -> 0
G18: =SUM(E18:F18) -> 0 | M18: =SUM(K18:L18) -> 0
G19: =SUM(E19:F19) -> 0 | M19: =SUM(K19:L19) -> 0
G20: =SUM(E20:F20) -> 0 | M20: =SUM(K20:L20) -> 0
G21: =SUM(E21:F21) -> 0
D27: Tổng | E27: =SUM(E4:E26) -> 23869147 | F27: =SUM(F4:F26) -> 1909533 | G27: =SUM(G4:G26) -> 25778680 | J27: Tổng | K27: =SUM(K4:K26) -> 10758842 | L27: =SUM(L4:L26) -> 854028 | M27: =SUM(M4:M26) -> 11612870

Sheet tháng 1-2025
B3: XUẤT HÓA ĐƠN | C3: Ngày | D3: Nội Dung | E3: Tiền | F3: Thuế | G3: Tổng tiền | H3: HÓA ĐƠN ĐẦU VÀO | I3: Ngày | J3: Nội Dung | K3: Tiền | L3: Thuế | M3: Tổng tiền
C4: 45658 | D4: tiền phòng 304 | E4: 8085100 | F4: 646808 | G4: =SUM(E4:F4) -> 8731908 | I4: 45659 | J4: tiền điện | K4: 7852984 | L4: 628239 | M4: =SUM(K4:L4) -> 8481223
C5: 45661 | D5: tiền phòng 704 Maltsev Vladimir | E5: 6481481 | F5: 518519 | G5: =SUM(E5:F5) -> 7000000 | I5: 45661 | J5: CMC | K5: 20186 | L5: 2019 | M5: =SUM(K5:L5) -> 22205
C6: 45676 | D6: phòng 702 - Gou jiang | E6: 833333 | F6: 66667 | G6: =SUM(E6:F6) -> 900000 | I6: 45659 | J6: Dasani | K6: 1574074 | L6: 125926 | M6: =SUM(K6:L6) -> 1700000
C7: 45676 | D7: phòng 402 - Ozerov | E7: 555556 | F7: 44444 | G7: =SUM(E7:F7) -> 600000 | I7: 45664 | J7: tiền rác | K7: 240909 | L7: 19273 | M7: =SUM(K7:L7) -> 260182
C8: 45676 | D8: phòng 604 - Kumar Bharat | E8: 6481481 | F8: 518519 | G8: =SUM(E8:F8) -> 7000000 | I8: 45671 | J8: tiền nước | K8: 1354764 | L8: 74311 | M8: =SUM(K8:L8) -> 1429075
C9: 45680 | D9: phòng 504 - Alena | E9: 6481481 | F9: 518519 | G9: =SUM(E9:F9) -> 7000000 | I9: 45688 | J9: tiền wifi | K9: 510455 | L9: 51046 | M9: =SUM(K9:L9) -> 561501
G10: =SUM(E10:F10) -> 0 | I10: 45688 | J10: ví vimo | K10: 118617 | L10: 11862 | M10: =SUM(K10:L10) -> 130479
G11: =SUM(E11:F11) -> 0 | I11: 45683 | J11: hóa đơn tiếp khách | K11: 1402000 | L11: 112160 | M11: =SUM(K11:L11) -> 1514160
G12: =SUM(E12:F12) -> 0 | I12: 45684 | J12: hóa đơn tiếp khách 2 | K12: 2087400 | L12: 168552 | M12: =SUM(K12:L12) -> 2255952
G13: =SUM(E13:F13) -> 0 | M13: =SUM(K13:L13) -> 0
G14: =SUM(E14:F14) -> 0 | M14: =SUM(K14:L14) -> 0
G15: =SUM(E15:F15) -> 0 | M15: =SUM(K15:L15) -> 0
G16: =SUM(E16:F16) -> 0 | M16: =SUM(K16:L16) -> 0
G17: =SUM(E17:F17) -> 0 | M17: =SUM(K17:L17) -> 0
G18: =SUM(E18:F18) -> 0 | M18: =SUM(K18:L18) -> 0
G19: =SUM(E19:F19) -> 0 | M19: =SUM(K19:L19) -> 0
G20: =SUM(E20:F20) -> 0 | M20: =SUM(K20:L20) -> 0
G21: =SUM(E21:F21) -> 0
D27: Tổng | E27: =SUM(E4:E26) -> 28918432 | F27: =SUM(F4:F26) -> 2313476 | G27: =SUM(G4:G26) -> 31231908 | J27: Tổng | K27: =SUM(K4:K26) -> 15161389 | L27: =SUM(L4:L26) -> 1193388 | M27: =SUM(M4:M26) -> 16354777

Sheet tháng 2-2025
B3: XUẤT HÓA ĐƠN | C3: Ngày | D3: Nội Dung | E3: Tiền | F3: Thuế | G3: Tổng tiền | H3: HÓA ĐƠN ĐẦU VÀO | I3: Ngày | J3: Nội Dung | K3: Tiền | L3: Thuế | M3: Tổng tiền
C4: 45690 | D4: Tiền phòng 702,703,502 out ngày 29/1 | E4: 5555556 | F4: 444444 | G4: =SUM(E4:F4) -> 6000000 | I4: 45690 | J4: hóa đơn tiếp khách | K4: 3971835 | L4: 317747 | M4: =SUM(K4:L4) -> 4289582
C5: 45691 | D5: tiền phòng 304 | E5: 8558700 | F5: 684696 | G5: =SUM(E5:F5) -> 9243396 | I5: 45689 | J5: hóa đơn tiếp khách 2 | K5: 2670150 | L5: 215271 | M5: =SUM(K5:L5) -> 2885421
C6: 45691 | D6: tiền phòng 404 Ko Sumin | E6: 6018519 | F6: 481481 | G6: =SUM(E6:F6) -> 6500000 | I6: 45699 | J6: hóa đơn tiếp khách 3 | K6: 1576000 | L6: 136640 | M6: =SUM(K6:L6) -> 1712640
C7: 45697 | D7: tiền phòng 402 - kira | E7: 1666667 | F7: 133333 | G7: =SUM(E7:F7) -> 1800000 | I7: 45690 | J7: tiền điện | K7: 12074670 | L7: 965974 | M7: =SUM(K7:L7) -> 13040644
C8: 45697 | D8: tiền phòng 502 - kumar | E8: 3703704 | F8: 296296 | G8: =SUM(E8:F8) -> 4000000 | I8: 45704 | J8: hóa đơn tiếp khách 4 | K8: 2450000 | L8: 197570 | M8: =SUM(K8:L8) -> 2647570
C9: 46009 | D9: tiền phòng 801 | E9: 8425926 | F9: 674074 | G9: =SUM(E9:F9) -> 9100000 | I9: 45692 | J9: CMC | K9: 20542 | L9: 2054 | M9: =SUM(K9:L9) -> 22596
C10: 45707 | D10: tiền phòng 402 Alena Vasileva | E10: 555556 | F10: 44444 | G10: =SUM(E10:F10) -> 600000 | I10: 45696 | J10: tiền nước | K10: 2128669 | L10: 115911 | M10: =SUM(K10:L10) -> 2244580
C11: 45707 | D11: tiền phòng 701 Fan jiajun | E11: 740741 | F11: 59259 | G11: =SUM(E11:F11) -> 800000 | I11: 45716 | J11: vimo | K11: 471955 | L11: 47195 | M11: =SUM(K11:L11) -> 519150
C12: 45707 | D12: tiền phòng 801 - sandeep | E12: 1944444 | F12: 155556 | G12: =SUM(E12:F12) -> 2100000 | I12: 45716 | J12: router wifi | K12: 800000 | L12: 80000 | M12: =SUM(K12:L12) -> 880000
C13: 45704 | D13: tiền phòng 602 - Marcus | E13: 3703694 | F13: 296296 | G13: =SUM(E13:F13) -> 3999990 | I13: 45716 | J13: tiền wifi | K13: 510455 | L13: 51046 | M13: =SUM(K13:L13) -> 561501
C14: 45713 | D14: tiền phòng 302 neuman | E14: 3611111 | F14: 288889 | G14: =SUM(E14:F14) -> 3900000 | I14: 45692 | J14: Tiền rác | K14: 240909 | L14: 19273 | M14: =SUM(K14:L14) -> 260182
C15: 45715 | D15: tiền phòng 301 tanaka | E15: 740741 | F15: 59259 | G15: =SUM(E15:F15) -> 800000 | M15: =SUM(K15:L15) -> 0
C16: 45710 | D16: tiền phòng 402 - LI xuanyu | E16: 833333 | F16: 66667 | G16: =SUM(E16:F16) -> 900000 | M16: =SUM(K16:L16) -> 0
G17: =SUM(E17:F17) -> 0 | M17: =SUM(K17:L17) -> 0
G18: =SUM(E18:F18) -> 0 | M18: =SUM(K18:L18) -> 0
G19: =SUM(E19:F19) -> 0 | M19: =SUM(K19:L19) -> 0
G20: =SUM(E20:F20) -> 0 | M20: =SUM(K20:L20) -> 0
G21: =SUM(E21:F21) -> 0
D27: Tổng | E27: =SUM(E4:E26) -> 46058692 | F27: =SUM(F4:F26) -> 3684694 | G27: =SUM(G4:G26) -> 49743386 | J27: Tổng | K27: =SUM(K4:K26) -> 26915185 | L27: =SUM(L4:L26) -> 2148681 | M27: =SUM(M4:M26) -> 29063866

Sheet tháng 3-2025
B3: XUẤT HÓA ĐƠN | C3: Ngày | D3: Nội Dung | E3: Tiền | F3: Thuế | G3: Tổng tiền | H3: HÓA ĐƠN ĐẦU VÀO | I3: Ngày | J3: Nội Dung | K3: Tiền | L3: Thuế | M3: Tổng tiền
C4: 45717 | D4: tiền phòng 402 niko | E4: 1388889 | F4: 111111 | G4: =SUM(E4:F4) -> 1500000 | I4: 45718 | J4: tiền điện | K4: 15771632 | L4: 1261731 | M4: =SUM(K4:L4) -> 17033363
C5: 45717 | D5: tiền phòng 701 joel massing | E5: 1481481 | F5: 118519 | G5: =SUM(E5:F5) -> 1600000 | I5: 45720 | J5: cmc | K5: 28958 | L5: 2896 | M5: =SUM(K5:L5) -> 31854
C6: 45717 | D6: tiền phòng 702 stefanovics | E6: 3888889 | F6: 311111 | G6: =SUM(E6:F6) -> 4200000 | I6: 45723 | J6: dịch vụ hóa đơn điện tử | K6: 800000 | L6: 80000 | M6: =SUM(K6:L6) -> 880000
C7: 45717 | D7: tiền phòng 304 | E7: 8432900 | F7: 674632 | G7: =SUM(E7:F7) -> 9107532 | I7: 45726 | J7: tiền nước | K7: 2111502 | L7: 114976 | M7: =SUM(K7:L7) -> 2226478
C8: 45719 | D8: tiền phòng 602 madalina | E8: 1944444 | F8: 155556 | G8: =SUM(E8:F8) -> 2100000 | I8: 45736 | J8: dasani | K8: 916667 | L8: 73333 | M8: =SUM(K8:L8) -> 990000
C9: 45723 | D9: tiền phòng 402 ming ke | E9: 555556 | F9: 44444 | G9: =SUM(E9:F9) -> 600000 | I9: 45726 | J9: tiền rác | K9: 240909 | L9: 19273 | M9: =SUM(K9:L9) -> 260182
C10: 45723 | D10: tiền phòng 501 Mykola Neveselyi | E10: 3333333 | F10: 266667 | G10: =SUM(E10:F10) -> 3600000 | I10: 45746 | J10: vimo | K10: 1063718 | L10: 106372 | M10: =SUM(K10:L10) -> 1170090
C11: 45723 | D11: tiền phòng 502 kindrick bradon | E11: 3333333 | F11: 266667 | G11: =SUM(E11:F11) -> 3600000 | I11: 45747 | J11: tiền wifi | K11: 510455 | L11: 51046 | M11: =SUM(K11:L11) -> 561501
C12: 45726 | D12: tiền phòng 302 Katie blann | E12: 277778 | F12: 22222 | G12: =SUM(E12:F12) -> 300000
C13: 45726 | D13: tiền phòng 302 Yucel Sengul | E13: 277778 | F13: 22222 | G13: =SUM(E13:F13) -> 300000
C14: 45726 | D14: tiền phòng 502 jie zan | E14: 555556 | F14: 44444 | G14: =SUM(E14:F14) -> 600000
C15: 45727 | D15: tiền phòng 702 Stepan | E15: 1944444 | F15: 155556 | G15: =SUM(E15:F15) -> 2100000
C16: 45727 | D16: tiền phòng 603 Laura do trang | E16: 1111111 | F16: 88889 | G16: =SUM(E16:F16) -> 1200000
C17: 45730 | D17: tiền phòng 703 Donaire Sarah | E17: 3402778 | F17: 272222 | G17: =SUM(E17:F17) -> 3675000
C18: 45731 | D18: tiền phòng 701 kabita | E18: 1481481 | F18: 118519 | G18: =SUM(E18:F18) -> 1600000
C19: 45732 | D19: tiền phòng 302 rebecca | E19: 555556 | F19: 44444 | G19: =SUM(E19:F19) -> 600000
C20: 45733 | D20: tiền phòng 402 Wei Zhixiong | E20: 277778 | F20: 22222 | G20: =SUM(E20:F20) -> 300000
C21: 45736 | D21: tiền phòng 402 graterol | E21: 555556 | F21: 44444 | G21: =SUM(E21:F21) -> 600000
C22: 45736 | D22: tiền phòng 702 Mariam Kyslytsia | E22: 1388889 | F22: 111111 | G22: =SUM(E22:F22) -> 1500000
C23: 45736 | D23: tiền phòng 602 setlovskyy | E23: 555556 | F23: 44444 | G23: =SUM(E23:F23) -> 600000
... C36: 45746 | D36: tiền phòng 801 thai ron | E36: 1296296 | F36: 103704 | G36: =SUM(E36:F36) -> 1400000
D37: Tổng | E37: =SUM(E4:E36) -> 58780123 | F37: =SUM(F4:F36) -> 4702409 | G37: =SUM(G4:G36) -> 63482532 | J37: Tổng | K37: =SUM(K4:K26) -> 21443841 | L37: =SUM(L4:L26) -> 1709627 | M37: =SUM(M4:M26) -> 23153468

Sheet tháng 4-2025
B3: XUẤT HÓA ĐƠN | C3: Ngày | D3: Nội Dung | E3: Tiền | F3: Thuế | G3: Tổng tiền | H3: HÓA ĐƠN ĐẦU VÀO | I3: Ngày | J3: Nội Dung | K3: Tiền | L3: Thuế | M3: Tổng tiền
C4: 45748 | D4: tiền phòng 703 LEKOMTSEVA OLGA | E4: 1111111 | F4: 88889 | G4: =SUM(E4:F4) -> 1200000 | I4: 45751 | J4: cmc | K4: 24203 | L4: 2420 | M4: =SUM(K4:L4) -> 26623
C5: 45748 | D5: tiền phòng 702 Isak Ziedorn | E5: 277778 | F5: 22222 | G5: =SUM(E5:F5) -> 300000 | I5: 45749 | J5: tiền điện | K5: 13089639 | L5: 1047171 | M5: =SUM(K5:L5) -> 14136810
C6: 45748 | D6: tiền phòng 501 Alexandr Burak | E6: 370370 | F6: 29630 | G6: =SUM(E6:F6) -> 400000 | I6: 45757 | J6: hóa đơn máy giặt | K6: 6309091 | L6: 630909 | M6: =SUM(K6:L6) -> 6940000
C7: 45748 | D7: tiền phòng 403 Kovalev Sergei | E7: 1481481 | F7: 118519 | G7: =SUM(E7:F7) -> 1600000 | I7: 45761 | J7: dasani | K7: 916667 | L7: 73333 | M7: =SUM(K7:L7) -> 990000
C8: 45748 | D8: tiền phòng 702 Nicolas Salvagno | E8: 833333 | F8: 66667 | G8: =SUM(E8:F8) -> 900000 | I8: 45759 | J8: nước giặt | K8: 1324000 | L8: 132400 | M8: =SUM(K8:L8) -> 1456400
C9: 45750 | D9: tiền phòng 304 | E9: 9091500 | F9: 727320 | G9: =SUM(E9:F9) -> 9818820 | I9: 45757 | J9: tiền nước | K9: 1871168 | L9: 101890 | M9: =SUM(K9:L9) -> 1973058
C10: 45752 | D10: tiền phòng 802 Miroi Evgenii | E10: 1388889 | F10: 111111 | G10: =SUM(E10:F10) -> 1500000 | I10: 45750 | J10: tiền rác | K10: 240909 | L10: 19273 | M10: =SUM(K10:L10) -> 260182
C11: 45756 | D11: tiền phòng 504 park hee ra | E11: 6481481 | F11: 518519 | G11: =SUM(E11:F11) -> 7000000 | I11: 45777 | J11: máy lọc nước | K11: 822918 | L11: 65832 | M11: =SUM(K11:L11) -> 888750
C12: 45759 | D12: tiền phòng 502 Curulli Dominic Italo | E12: 277778 | F12: 22222 | G12: =SUM(E12:F12) -> 300000 | I12: 45776 | J12: vimo | K12: 708170 | L12: 70817 | M12: =SUM(K12:L12) -> 778987
C13: 45762 | D13: tiền phòng đoàn Văn Thị Tuyết | E13: 3148148 | F13: 251852 | G13: =SUM(E13:F13) -> 3400000 | I13: 45777 | J13: tiền wifi | K13: 510455 | L13: 51046 | M13: =SUM(K13:L13) -> 561501
C14: 45762 | D14: tiền phòng 502 Ý Ly | E14: 277778 | F14: 22222 | G14: =SUM(E14:F14) -> 300000
C15: 45762 | D15: tiền phòng 702 Igor Kovaltchouk | E15: 1666667 | F15: 133333 | G15: =SUM(E15:F15) -> 1800000
C16: 45763 | D16: tiền phòng 901 ZHENG QIN | E16: 1296296 | F16: 103704 | G16: =SUM(E16:F16) -> 1400000
C17: 45766 | D17: tiền phòng 704 tân tiến senko | E17: 1000000 | F17: 80000 | G17: =SUM(E17:F17) -> 1080000
C18: 45770 | D18: tiền phòng 802 Miroi Evgenii | E18: 3750000 | F18: 300000 | G18: =SUM(E18:F18) -> 4050000
C19: 45771 | D19: tiền phòng 302 Hsi-hung lin | E19: 555556 | F19: 44444 | G19: =SUM(E19:F19) -> 600000
C20: 45771 | D20: tiền phòng 902 miroi evgenii | E20: 925926 | F20: 74074 | G20: =SUM(E20:F20) -> 1000000
C21: 45775 | D21: tiền phòng 504- Vân | E21: 1111111 | F21: 88889 | G21: =SUM(E21:F21) -> 1200000
G22: =SUM(E22:F22) -> 0
G23: =SUM(E23:F23) -> 0
G24: =SUM(E24:F24) -> 0
G25: =SUM(E25:F25) -> 0
G26: =SUM(E26:F26) -> 0
G27: =SUM(E27:F27) -> 0
G28: =SUM(E28:F28) -> 0
G29: =SUM(E29:F29) -> 0
G30: =SUM(E30:F30) -> 0
G31: =SUM(E31:F31) -> 0
G32: =SUM(E32:F32) -> 0
G33: =SUM(E33:F33) -> 0
... G35: =SUM(E35:F35) -> 0
D37: Tổng | E37: =SUM(E4:E35) -> 35045203 | F37: =SUM(F4:F35) -> 2803617 | G37: =SUM(G4:G35) -> 37848820 | J37: Tổng | K37: =SUM(K4:K26) -> 25817220 | L37: =SUM(L4:L26) -> 2195091 | M37: =SUM(M4:M26) -> 28012311

Sheet tháng 5-2025
B3: XUẤT HÓA ĐƠN | C3: Ngày | D3: Nội Dung | E3: Tiền | F3: Thuế | G3: Tổng tiền | H3: HÓA ĐƠN ĐẦU VÀO | I3: Ngày | J3: Nội Dung | K3: Tiền | L3: Thuế | M3: Tổng tiền
C4: 45778 | D4: Tiền phòng 304 | E4: 9113700 | F4: 729096 | G4: =SUM(E4:F4) -> 9842796 | I4: 45778 | J4: ấm siêu tốc | K4: 381819 | L4: 38181 | M4: =SUM(K4:L4) -> 420000
C5: 45778 | D5: tiền phòng 404 Golosova Iuliia | E5: 4629630 | F5: 370370 | G5: =SUM(E5:F5) -> 5000000 | I5: 45779 | J5: tiền điện | K5: 11068016 | L5: 885441 | M5: =SUM(K5:L5) -> 11953457
C6: 45778 | D6: tiền phòng 301 - Vân | E6: 555556 | F6: 44444 | G6: =SUM(E6:F6) -> 600000 | I6: 45781 | J6: CMC | K6: 22710 | L6: 2271 | M6: =SUM(K6:L6) -> 24981
C7: 45781 | D7: tiền phòng 601- Nguyễn T Thu Hương | E7: 370370 | F7: 29630 | G7: =SUM(E7:F7) -> 400000 | I7: 45786 | J7: tiền nước | K7: 2042836 | L7: 111236 | M7: =SUM(K7:L7) -> 2154072
C8: 45781 | D8: tiền phòng 901 - Ngọc Anh | E8: 1296296 | F8: 103704 | G8: =SUM(E8:F8) -> 1400000 | I8: 45804 | J8: tiền nước giặt | K8: 1975000 | L8: 197500 | M8: =SUM(K8:L8) -> 2172500
C9: 45781 | D9: tiền phòng 602 Lorenzo | E9: 1388889 | F9: 111111 | G9: =SUM(E9:F9) -> 1500000 | I9: 45799 | J9: dasani | K9: 916667 | L9: 73333 | M9: =SUM(K9:L9) -> 990000
C10: 45781 | D10: tiền phòng 603 Thanh Hường | E10: 370370 | F10: 29630 | G10: =SUM(E10:F10) -> 400000 | I10: 45807 | J10: vimo | K10: 475801 | L10: 47580 | M10: =SUM(K10:L10) -> 523381
C11: 45781 | D11: tiền phòng 701 Htan Ywee Lan | E11: 370370 | F11: 29630 | G11: =SUM(E11:F11) -> 400000 | I11: 45785 | J11: tiền rác | K11: 240909 | L11: 19273 | M11: =SUM(K11:L11) -> 260182
C12: 45781 | D12: tiền phòng 504 - cao thị yến | E12: 1111111 | F12: 88889 | G12: =SUM(E12:F12) -> 1200000 | I12: 45808 | J12: tiền wifi | K12: 510455 | L12: 51046 | M12: =SUM(K12:L12) -> 561501
C13: 45781 | D13: tiền phòng Chị Nhung | E13: 11666667 | F13: 933333 | G13: =SUM(E13:F13) -> 12600000
C14: 45781 | D14: tiền phòng Tố Uyên | E14: 11851851 | F14: 948149 | G14: =SUM(E14:F14) -> 12800000
C15: 45783 | D15: tiền phòng 902 miroi evgenii | E15: 4583333 | F15: 366667 | G15: =SUM(E15:F15) -> 4950000
C16: 45788 | D16: tiền phòng 402 Ellie Humphrey | E16: 277778 | F16: 22222 | G16: =SUM(E16:F16) -> 300000
C17: 45790 | D17: tiền phòng 901,902 Đình Dinh | E17: 3333333 | F17: 266667 | G17: =SUM(E17:F17) -> 3600000
C18: 45798 | D18: tiền phòng 602 Kim Jonghwan | E18: 555556 | F18: 44444 | G18: =SUM(E18:F18) -> 600000
C19: 45798 | D19: tiền phòng 703 Olga Gurinovich | E19: 2592593 | F19: 207407 | G19: =SUM(E19:F19) -> 2800000
C20: 45798 | D20: tiền phòng 802 chimitova valentina | E20: 5555556 | F20: 444444 | G20: =SUM(E20:F20) -> 6000000
C21: 45804 | D21: tiền phòng 302 Kim Jonghwan | E21: 277778 | F21: 22222 | G21: =SUM(E21:F21) -> 300000
G22: =SUM(E22:F22) -> 0
G23: =SUM(E23:F23) -> 0
G24: =SUM(E24:F24) -> 0
G25: =SUM(E25:F25) -> 0
G26: =SUM(E26:F26) -> 0
G27: =SUM(E27:F27) -> 0
G28: =SUM(E28:F28) -> 0
G29: =SUM(E29:F29) -> 0
G30: =SUM(E30:F30) -> 0
G31: =SUM(E31:F31) -> 0
G32: =SUM(E32:F32) -> 0
G33: =SUM(E33:F33) -> 0
... G35: =SUM(E35:F35) -> 0
D37: Tổng | E37: =SUM(E4:E35) -> 59900737 | F37: =SUM(F4:F35) -> 4792059 | G37: =SUM(G4:G35) -> 64692796 | J37: Tổng | K37: =SUM(K4:K26) -> 17634213 | L37: =SUM(L4:L26) -> 1425861 | M37: =SUM(M4:M26) -> 19060074

Sheet tháng 6-2025
B3: XUẤT HÓA ĐƠN | C3: Ngày | D3: Nội Dung | E3: Tiền | F3: Thuế | G3: Tổng tiền | H3: HÓA ĐƠN ĐẦU VÀO | I3: Ngày | J3: Nội Dung | K3: Tiền | L3: Thuế | M3: Tổng tiền
C4: 45809 | D4: Tiền phòng 301,302 Xuân Hòa | E4: 833333 | F4: 66667 | G4: =SUM(E4:F4) -> 900000 | I4: 45811 | J4: Chống thấm | K4: 33000000 | L4: 2640000 | M4: =SUM(K4:L4) -> 35640000
C5: 45809 | D5: tiền phòng 402 ngô thị hiền | E5: 370370 | F5: 29630 | G5: =SUM(E5:F5) -> 400000 | I5: 45812 | J5: cmc | K5: 20324 | L5: 2032 | M5: =SUM(K5:L5) -> 22356
C6: 45809 | D6: tiền phòng 502 mạnh quang | E6: 370370 | F6: 29630 | G6: =SUM(E6:F6) -> 400000 | I6: 45812 | J6: phí dịch vụ asm | K6: 3500 | L6: 350 | M6: =SUM(K6:L6) -> 3850
C7: 45809 | D7: tiền phòng 702 ngọc hà | E7: 370370 | F7: 29630 | G7: =SUM(E7:F7) -> 400000 | I7: 45813 | J7: ASM | K7: 1980000 | L7: 198000 | M7: =SUM(K7:L7) -> 2178000
C8: 45809 | D8: tiền phòng 703 Phi Hùng (901 Vy Nguyen) | E8: 462963 | F8: 37037 | G8: =SUM(E8:F8) -> 500000 | I8: 45810 | J8: tiền điện | K8: 13772275 | L8: 1101782 | M8: =SUM(K8:L8) -> 14874057
C9: 45809 | D9: tiền phòng 304 | E9: 8947200 | F9: 715776 | G9: =SUM(E9:F9) -> 9662976 | I9: 45817 | J9: tiền nước | K9: 1527835 | L9: 83194 | M9: =SUM(K9:L9) -> 1611029
C10: 45811 | D10: tiền phòng 404 Golosova Iuliia | E10: 4629630 | F10: 370370 | G10: =SUM(E10:F10) -> 5000000 | I10: 45821 | J10: dasani | K10: 1092593 | L10: 87407 | M10: =SUM(K10:L10) -> 1180000
C11: 45815 | D11: tiền phòng 602,603 Aaniaa Jamil | E11: 648148 | F11: 51852 | G11: =SUM(E11:F11) -> 700000 | I11: 45819 | J11: tiền rác | K11: 240909 | L11: 19273 | M11: =SUM(K11:L11) -> 260182
C12: 45816 | D12: tiền phòng 503 Văn Nguyên | E12: 416667 | F12: 33333 | G12: =SUM(E12:F12) -> 450000 | I12: 45838 | J12: vimo | K12: 39795 | L12: 3980 | M12: =SUM(K12:L12) -> 43775
C13: 45816 | D13: tiền phòng 402 Giang Nguyen | E13: 370370 | F13: 29630 | G13: =SUM(E13:F13) -> 400000 | I13: 45838 | J13: tiền wifi | K13: 510455 | L13: 51046 | M13: =SUM(K13:L13) -> 561501
C14: 45816 | D14: tiền phòng 403 Hồ Thị Hùy | E14: 462963 | F14: 37037 | G14: =SUM(E14:F14) -> 500000
C15: 45816 | D15: tiền phòng 502 Xuân Hiệp | E15: 370370 | F15: 29630 | G15: =SUM(E15:F15) -> 400000
C16: 45816 | D16: tiền phòng 602 Nguyễn Thị Thủy | E16: 370370 | F16: 29630 | G16: =SUM(E16:F16) -> 400000
C17: 45816 | D17: tiền phòng 601,603 Chloe Lim Wanting | E17: 1851852 | F17: 148148 | G17: =SUM(E17:F17) -> 2000000
C18: 45817 | D18: tiền phòng 301 Phạm Thị Oanh | E18: 1388889 | F18: 111111 | G18: =SUM(E18:F18) -> 1500000
C19: 45817 | D19: tiền phòng 302 Nguyễn Lương Trọng | E19: 740741 | F19: 59259 | G19: =SUM(E19:F19) -> 800000
C20: 45823 | D20: tiền phòng 403 Việt Hà | E20: 925926 | F20: 74074 | G20: =SUM(E20:F20) -> 1000000
C21: 45823 | D21: tiền phòng 601- Vũ Minh Đức | E21: 462963 | F21: 37037 | G21: =SUM(E21:F21) -> 500000
C22: 45823 | D22: tiền phòng 302,502 Chong Dongmoon | E22: 740740 | F22: 59260 | G22: =SUM(E22:F22) -> 800000
C23: 45823 | D23: tiền phòng Ngo phuong loan | E23: 3611110 | F23: 288890 | G23: =SUM(E23:F23) -> 3900000
C24: 45823 | D24: tiền phòng 702 Chimitov | E24: 3148148 | F24: 251852 | G24: =SUM(E24:F24) -> 3400000
C25: 45825 | D25: tiền phòng Trần Thu Thủy | E25: 9259260 | F25: 740742 | G25: =SUM(E25:F25) -> 10000002
... C47: 45837 | D47: tiền phòng 702 Nam Thành | E47: 370370 | F47: 29630 | G47: =SUM(E47:F47) -> 400000
G48: =SUM(E48:F48) -> 0
D49: Tổng | E49: =SUM(E4:E47) -> 73993491 | F49: =SUM(F4:F47) -> 5919487 | G49: =SUM(G4:G47) -> 79912978 | J49: Tổng | K49: =SUM(K4:K26) -> 52187686 | L49: =SUM(L4:L26) -> 4187064 | M49: =SUM(M4:M26) -> 56374750

Sheet tháng 7-2025
B3: XUẤT HÓA ĐƠN | C3: Ngày | D3: Nội Dung | E3: Tiền | F3: Thuế | G3: Tổng tiền | H3: HÓA ĐƠN ĐẦU VÀO | I3: Ngày | J3: Nội Dung | K3: Tiền | L3: Thuế | M3: Tổng tiền
C4: 45839 | D4: tiền phòng 301 Lê Thị Hà | E4: 925926 | F4: 74074 | G4: =SUM(E4:F4) -> 1000000 | I4: 45840 | J4: tiền điện | K4: 20800242 | L4: 1664019 | M4: =SUM(K4:L4) -> 22464261
C5: 45839 | D5: tiền phòng 402,403 Vũ Hợp | E5: 2500000 | F5: 200000 | G5: =SUM(E5:F5) -> 2700000 | I5: 45843 | J5: cmc | K5: 28557 | L5: 2856 | M5: =SUM(K5:L5) -> 31413
C6: 45839 | D6: tiền phòng 704 chị Huyền | E6: 1944444 | F6: 155556 | G6: =SUM(E6:F6) -> 2100000 | I6: 45852 | J6: tiền nước giặt | K6: 1645000 | L6: 131600 | M6: =SUM(K6:L6) -> 1776600
C7: 45839 | D7: tiền phòng 502 Văn Phòng | E7: 370370 | F7: 29630 | G7: =SUM(E7:F7) -> 400000 | I7: 45849 | J7: tiền rác | K7: 240909 | L7: 19273 | M7: =SUM(K7:L7) -> 260182
C8: 45839 | D8: tiền phòng 901 Minh Vũ | E8: 833333 | F8: 66667 | G8: =SUM(E8:F8) -> 900000 | I8: 45859 | J8: ổ nối điện | K8: 822222 | L8: 65778 | M8: =SUM(K8:L8) -> 888000
C9: 45839 | D9: tiền phòng 701,703 Nguyen Kathy | E9: 925926 | F9: 74074 | G9: =SUM(E9:F9) -> 1000000 | I9: 45849 | J9: tiền nước | K9: 2626503 | L9: 143020 | M9: =SUM(K9:L9) -> 2769523
C10: 45839 | D10: tiền phòng 304 | E10: 9709400 | F10: 776752 | G10: =SUM(E10:F10) -> 10486152 | I10: 45863 | J10: dasani | K10: 1833333 | L10: 146667 | M10: =SUM(K10:L10) -> 1980000
C11: 45839 | D11: tiền phòng 802 Chimitova | E11: 5555556 | F11: 444444 | G11: =SUM(E11:F11) -> 6000000 | I11: 45866 | J11: Dasani | K11: 916667 | L11: 73333 | M11: =SUM(K11:L11) -> 990000
C12: 45840 | D12: tiền phòng 902 Dũng Tạ | E12: 804630 | F12: 64370 | G12: =SUM(E12:F12) -> 869000 | I12: 45869 | J12: vimo | K12: 394250 | L12: 39425 | M12: =SUM(K12:L12) -> 433675
C13: 45842 | D13: tiền phòng 801,901 Đỗ Việt Hà | E13: 1666666 | F13: 133334 | G13: =SUM(E13:F13) -> 1800000 | I13: 45869 | J13: tiền wifi | K13: 510455 | L13: 51046 | M13: =SUM(K13:L13) -> 561501
C14: 45842 | D14: tiền phòng 704 Nhật Nguyễn | E14: 1154630 | F14: 92370 | G14: =SUM(E14:F14) -> 1247000 | I14: 45845 | J14: Bàn chải | K14: 2040000 | L14: 192000 | M14: =SUM(K14:L14) -> 2232000
C15: 45844 | D15: tiền phòng 602 Hương Thu | E15: 1944444 | F15: 155556 | G15: =SUM(E15:F15) -> 2100000 | I15: 45848 | J15: dasani | K15: 916667 | L15: 73333 | M15: =SUM(K15:L15) -> 990000
C16: 45844 | D16: tiền phòng 402,502 Mỹ Hạnh | E16: 1481482 | F16: 118518 | G16: =SUM(E16:F16) -> 1600000
C17: 45844 | D17: tiền phòng Xuân Trường | E17: 12500000 | F17: 1000000 | G17: =SUM(E17:F17) -> 13500000
C18: 45845 | D18: tiền phòng 702 | E18: 648148 | F18: 51852 | G18: =SUM(E18:F18) -> 700000
C19: 45845 | D19: tiền phòng 602 Văn Hùng | E19: 1111111 | F19: 88889 | G19: =SUM(E19:F19) -> 1200000
C20: 45851 | D20: tiền phòng Đồng Xèng | E20: 19444447 | F20: 1555553 | G20: =SUM(E20:F20) -> 21000000
C21: 45851 | D21: tiền phòng 602 phương anh nguyễn | E21: 462963 | F21: 37037 | G21: =SUM(E21:F21) -> 500000
C22: 45851 | D22: tiền phòng 302 Đạt Đỗ | E22: 1481481 | F22: 118519 | G22: =SUM(E22:F22) -> 1600000
C23: 45851 | D23: tiền phòng Cao Thị Nhị | E23: 4444443 | F23: 355557 | G23: =SUM(E23:F23) -> 4800000
C24: 45852 | D24: tiền phòng 702,703 Kiều Minh Nhi | E24: 2592593 | F24: 207407 | G24: =SUM(E24:F24) -> 2800000
C25: 45852 | D25: tiền phòng 404 Thành Nguyễn | E25: 2222222 | F25: 177778 | G25: =SUM(E25:F25) -> 2400000
C26: 45858 | D26: tiền phòng 502 Guldana Nuskabayeva | E26: 740741 | F26: 59259 | G26: =SUM(E26:F26) -> 800000
C27: 45858 | D27: tiền phòng 701 Daniela Fusar Poli | E27: 1388889 | F27: 111111 | G27: =SUM(E27:F27) -> 1500000
... C49: 45867 | D49: tiền phòng 403 Sherwell | E49: 1111111 | F49: 88889 | G49: =SUM(E49:F49) -> 1200000
D50: Tổng | E50: =SUM(E4:E49) -> 113335327 | F50: =SUM(F4:F49) -> 9066825 | G50: =SUM(G4:G49) -> 122402152 | J50: Tổng | K50: =SUM(K4:K28) -> 32774805 | L50: =SUM(L4:L28) -> 2602350 | M50: =SUM(M4:M28) -> 35377155

Sheet tháng 8-2025
B3: XUẤT HÓA ĐƠN | C3: Ngày | D3: Nội Dung | E3: Tiền | F3: Thuế | G3: Tổng tiền | H3: HÓA ĐƠN ĐẦU VÀO | I3: Ngày | J3: Nội Dung | K3: Tiền | L3: Thuế | M3: Tổng tiền
C4: 45870 | D4: tiền phòng 502 Wilfred Lee | E4: 1388889 | F4: 111111 | G4: =SUM(E4:F4) -> 1500000 | I4: 45873 | J4: cmc | K4: 27999 | L4: 2800 | M4: =SUM(K4:L4) -> 30799
C5: 45870 | D5: tiền phòng 702 Fang Weihao | E5: 833333 | F5: 66667 | G5: =SUM(E5:F5) -> 900000 | I5: 45871 | J5: tiền điện | K5: 27790128 | L5: 2223210 | M5: =SUM(K5:L5) -> 30013338
C6: 45870 | D6: tiền phòng 304 | E6: 9579900 | F6: 766392 | G6: =SUM(E6:F6) -> 10346292 | I6: 45883 | J6: khăn tắm | K6: 1200000 | L6: 96000 | M6: =SUM(K6:L6) -> 1296000
C7: 45871 | D7: tiền phòng 801 Cao Nguyên Việt | E7: 2592593 | F7: 207407 | G7: =SUM(E7:F7) -> 2800000 | I7: 45885 | J7: tấm trang trí | K7: 24910000 | L7: 1992800 | M7: =SUM(K7:L7) -> 26902800
C8: 45871 | D8: tiền phòng 701 Cao Nguyên Việt | E8: 925926 | F8: 74074 | G8: =SUM(E8:F8) -> 1000000 | I8: 45881 | J8: tiền rác | K8: 240909 | L8: 19273 | M8: =SUM(K8:L8) -> 260182
C9: 45876 | D9: tiền phòng 502 Li Jinling | E9: 833333 | F9: 66667 | G9: =SUM(E9:F9) -> 900000 | I9: 45880 | J9: tiền nước | K9: 2849670 | L9: 155170 | M9: =SUM(K9:L9) -> 3004840
C10: 45878 | D10: tiền phòng 702,703 Alolayan Salwa Abudullah A | E10: 3240741 | F10: 259259 | G10: =SUM(E10:F10) -> 3500000 | I10: 45899 | J10: vimo | K10: 669904 | L10: 66990 | M10: =SUM(K10:L10) -> 736894
C11: 45878 | D11: tiền phòng 402 Konnur Basavaraj | E11: 555556 | F11: 44444 | G11: =SUM(E11:F11) -> 600000 | I11: 45900 | J11: tiền wifi | K11: 510455 | L11: 51046 | M11: =SUM(K11:L11) -> 561501
C12: 45880 | D12: tiền phòng 703 Mohammad Tousif | E12: 740741 | F12: 59259 | G12: =SUM(E12:F12) -> 800000 | I12: 45895 | J12: dasani | K12: 916667 | L12: 73333 | M12: =SUM(K12:L12) -> 990000
C13: 45880 | D13: tiền phòng 404 Tấn Vinh | E13: 1296296 | F13: 103704 | G13: =SUM(E13:F13) -> 1400000
C14: 45884 | D14: tiền phòng 602 Siu Man Kit | E14: 277778 | F14: 22222 | G14: =SUM(E14:F14) -> 300000
C15: 45888 | D15: tiền phòng 402 Coppola | E15: 833333 | F15: 66667 | G15: =SUM(E15:F15) -> 900000
C16: 45888 | D16: tiền phòng 702 Lê Thị Na | E16: 1111111 | F16: 88889 | G16: =SUM(E16:F16) -> 1200000
C17: 45888 | D17: tiền phòng 802 Chimitova valentina | E17: 5555556 | F17: 444444 | G17: =SUM(E17:F17) -> 6000000
C18: 45891 | D18: tiền phòng 602 Moore Lindsay | E18: 833333 | F18: 66667 | G18: =SUM(E18:F18) -> 900000
C19: 45893 | D19: tiền phòng 704 Bảo Toàn | E19: 648148 | F19: 51852 | G19: =SUM(E19:F19) -> 700000
C20: 45900 | D20: tiền phòng 801 Thanh Tuyen Pham | E20: 1111111 | F20: 88889 | G20: =SUM(E20:F20) -> 1200000
G21: =SUM(E21:F21) -> 0
G22: =SUM(E22:F22) -> 0
G23: =SUM(E23:F23) -> 0
G24: =SUM(E24:F24) -> 0
G25: =SUM(E25:F25) -> 0
G26: =SUM(E26:F26) -> 0
G27: =SUM(E27:F27) -> 0
G28: =SUM(E28:F28) -> 0
D29: Tổng | E29: =SUM(E4:E28) -> 32357678 | F29: =SUM(F4:F28) -> 2588614 | G29: =SUM(G4:G28) -> 34946292 | J29: Tổng | K29: =SUM(K4:K26) -> 59115732 | L29: =SUM(L4:L26) -> 4680622 | M29: =SUM(M4:M26) -> 63796354

Sheet tháng 9-2025
B3: XUẤT HÓA ĐƠN | C3: Ngày | D3: Nội Dung | E3: Tiền | F3: Thuế | G3: Tổng tiền | H3: HÓA ĐƠN ĐẦU VÀO | I3: Ngày | J3: Nội Dung | K3: Tiền | L3: Thuế | M3: Tổng tiền
C4: 45904 | D4: tiền phòng 602 Hung Truong | E4: 555556 | F4: 44444 | G4: =SUM(E4:F4) -> 600000 | I4: 45904 | J4: CMC | K4: 23877 | L4: 2388 | M4: =SUM(K4:L4) -> 26265
C5: 45901 | D5: tiền phòng 304 | E5: 9576200 | F5: 766096 | G5: =SUM(E5:F5) -> 10342296 | I5: 45902 | J5: tiền điện | K5: 16323446 | L5: 1305876 | M5: =SUM(K5:L5) -> 17629322
C6: 45906 | D6: tiền phòng 901 Nguyen Le Uyen | E6: 4259259 | F6: 340741 | G6: =SUM(E6:F6) -> 4600000 | I6: 45909 | J6: chữ ký số | K6: 1400000 | L6: 112000 | M6: =SUM(K6:L6) -> 1512000
C7: 45907 | D7: tiền phòng 602 Lệ Lê | E7: 555556 | F7: 44444 | G7: =SUM(E7:F7) -> 600000 | I7: 45918 | J7: tiền rác | K7: 240909 | L7: 19273 | M7: =SUM(K7:L7) -> 260182
C8: 45919 | D8: tiền phòng 901 Lily Rose Clarke | E8: 1944444 | F8: 155556 | G8: =SUM(E8:F8) -> 2100000 | I8: 45911 | J8: tiền nước | K8: 995668 | L8: 54216 | M8: =SUM(K8:L8) -> 1049884
C9: 45929 | D9: tiền phòng 502 Jan Hubert | E9: 277778 | F9: 22222 | G9: =SUM(E9:F9) -> 300000 | I9: 45930 | J9: vimo | K9: 93864 | L9: 9386 | M9: =SUM(K9:L9) -> 103250
G10: =SUM(E10:F10) -> 0 | I10: 45930 | J10: tiền wifi | K10: 510455 | L10: 51046 | M10: =SUM(K10:L10) -> 561501
G11: =SUM(E11:F11) -> 0 | M11: =SUM(K11:L11) -> 0
G12: =SUM(E12:F12) -> 0
G13: =SUM(E13:F13) -> 0
G14: =SUM(E14:F14) -> 0
G15: =SUM(E15:F15) -> 0
G16: =SUM(E16:F16) -> 0
G17: =SUM(E17:F17) -> 0
G18: =SUM(E18:F18) -> 0
G19: =SUM(E19:F19) -> 0
G20: =SUM(E20:F20) -> 0
G21: =SUM(E21:F21) -> 0
G22: =SUM(E22:F22) -> 0
G23: =SUM(E23:F23) -> 0
... G28: =SUM(E28:F28) -> 0
D29: Tổng | E29: =SUM(E4:E28) -> 17168793 | F29: =SUM(F4:F28) -> 1373503 | G29: =SUM(G4:G28) -> 18542296 | J29: Tổng | K29: =SUM(K4:K26) -> 19588219 | L29: =SUM(L4:L26) -> 1554185 | M29: =SUM(M4:M26) -> 21142404

Sheet tháng 10-2025
B3: XUẤT HÓA ĐƠN | C3: Ngày | D3: Nội Dung | E3: Tiền | F3: Thuế | G3: Tổng tiền | H3: HÓA ĐƠN ĐẦU VÀO | I3: Ngày | J3: Nội Dung | K3: Tiền | L3: Thuế | M3: Tổng tiền
C4: 45934 | D4: tiền phòng 304 | E4: 9402300 | F4: 752184 | G4: =SUM(E4:F4) -> 10154484 | I4: 45934 | J4: CMC | K4: 20800 | L4: 2080 | M4: =SUM(K4:L4) -> 22880
C5: 45934 | D5: tiền phòng 504 Ky Nam | E5: 4629630 | F5: 370370 | G5: =SUM(E5:F5) -> 5000000 | I5: 45932 | J5: tiền điện | K5: 13912536 | L5: 1113003 | M5: =SUM(K5:L5) -> 15025539
C6: 45934 | D6: tiền phòng 302 Ti Chau | E6: 277778 | F6: 22222 | G6: =SUM(E6:F6) -> 300000 | I6: 45936 | J6: phần mềm Win | K6: 1500000 | L6: 120000 | M6: =SUM(K6:L6) -> 1620000
C7: 45937 | D7: tiền phòng 702 Hans Thorsten | E7: 5555556 | F7: 444444 | G7: =SUM(E7:F7) -> 6000000 | I7: 45941 | J7: tiền nước | K7: 858335 | L7: 46738 | M7: =SUM(K7:L7) -> 905073
C8: 45941 | D8: tiền phòng 704,801 Vĩnh Hạnh | E8: 1018519 | F8: 81481 | G8: =SUM(E8:F8) -> 1100000 | I8: 45951 | J8: tiền rác | K8: 240909 | L8: 19273 | M8: =SUM(K8:L8) -> 260182
C9: 45957 | D9: tiền phòng 702 Hsu | E9: 833333 | F9: 66667 | G9: =SUM(E9:F9) -> 900000 | I9: 45961 | J9: tiền wifi | K9: 510455 | L9: 51046 | M9: =SUM(K9:L9) -> 561501
G10: =SUM(E10:F10) -> 0 | M10: =SUM(K10:L10) -> 0
G11: =SUM(E11:F11) -> 0 | M11: =SUM(K11:L11) -> 0
G12: =SUM(E12:F12) -> 0
G13: =SUM(E13:F13) -> 0
G14: =SUM(E14:F14) -> 0
G15: =SUM(E15:F15) -> 0
G16: =SUM(E16:F16) -> 0
G17: =SUM(E17:F17) -> 0
G18: =SUM(E18:F18) -> 0
G19: =SUM(E19:F19) -> 0
G20: =SUM(E20:F20) -> 0
G21: =SUM(E21:F21) -> 0
G22: =SUM(E22:F22) -> 0
G23: =SUM(E23:F23) -> 0
... G28: =SUM(E28:F28) -> 0
D29: Tổng | E29: =SUM(E4:E28) -> 21717116 | F29: =SUM(F4:F28) -> 1737368 | G29: =SUM(G4:G28) -> 23454484 | J29: Tổng | K29: =SUM(K4:K26) -> 17043035 | L29: =SUM(L4:L26) -> 1352140 | M29: =SUM(M4:M26) -> 18395175

Sheet tháng 11-2025 
B3: XUẤT HÓA ĐƠN | C3: Ngày | D3: Nội Dung | E3: Tiền | F3: Thuế | G3: Tổng tiền | H3: HÓA ĐƠN ĐẦU VÀO | I3: Ngày | J3: Nội Dung | K3: Tiền | L3: Thuế | M3: Tổng tiền
C4: 45963 | D4: tiền phòng 304 | E4: 9028600 | F4: 722288 | G4: =SUM(E4:F4) -> 9750888 | I4: 45963 | J4: tiền điện | K4: 8278894 | L4: 662312 | M4: =SUM(K4:L4) -> 8941206
C5: 45963 | D5: tiền phòng 402 Chang Wonjae | E5: 277778 | F5: 22222 | G5: =SUM(E5:F5) -> 300000 | I5: 45965 | J5: cmc | K5: 20371 | L5: 2037 | M5: =SUM(K5:L5) -> 22408
C6: 45971 | D6: tiền phòng 404 - Lukin Vasyl | E6: 4629630 | F6: 370370 | G6: =SUM(E6:F6) -> 5000000 | I6: 45972 | J6: tiền nước | K6: 635168 | L6: 34586 | M6: =SUM(K6:L6) -> 669754
C7: 45981 | D7: tiền phòng 604 Vĩnh Hạnh | E7: 1018519 | F7: 81481 | G7: =SUM(E7:F7) -> 1100000 | I7: 45973 | J7: tiền rác | K7: 240909 | L7: 19273 | M7: =SUM(K7:L7) -> 260182
C8: 45984 | D8: tiền phòng 802 Thành Dĩnh | E8: 1283333 | F8: 102667 | G8: =SUM(E8:F8) -> 1386000 | I8: 45978 | J8: Bảo hiểm | K8: 9000000 | L8: 900000 | M8: =SUM(K8:L8) -> 9900000
G9: =SUM(E9:F9) -> 0 | I9: 45991 | J9: tiền wifi | K9: 510455 | L9: 51046 | M9: =SUM(K9:L9) -> 561501
G10: =SUM(E10:F10) -> 0 | M10: =SUM(K10:L10) -> 0
G11: =SUM(E11:F11) -> 0 | M11: =SUM(K11:L11) -> 0
G12: =SUM(E12:F12) -> 0
G13: =SUM(E13:F13) -> 0
G14: =SUM(E14:F14) -> 0
G15: =SUM(E15:F15) -> 0
G16: =SUM(E16:F16) -> 0
G17: =SUM(E17:F17) -> 0
G18: =SUM(E18:F18) -> 0
G19: =SUM(E19:F19) -> 0
G20: =SUM(E20:F20) -> 0
G21: =SUM(E21:F21) -> 0
G22: =SUM(E22:F22) -> 0
G23: =SUM(E23:F23) -> 0
... G28: =SUM(E28:F28) -> 0
D29: Tổng | E29: =SUM(E4:E28) -> 16237860 | F29: =SUM(F4:F28) -> 1299028 | G29: =SUM(G4:G28) -> 17536888 | J29: Tổng | K29: =SUM(K4:K26) -> 18685797 | L29: =SUM(L4:L26) -> 1669254 | M29: =SUM(M4:M26) -> 20355051

Sheet tháng 12-2025
B3: XUẤT HÓA ĐƠN | C3: Ngày | D3: Nội Dung | E3: Tiền | F3: Thuế | G3: Tổng tiền | H3: HÓA ĐƠN ĐẦU VÀO | I3: Ngày | J3: Nội Dung | K3: Tiền | L3: Thuế | M3: Tổng tiền
C4: 45992 | D4: tiền phòng 304 | E4: 8418100 | F4: 673448 | G4: =SUM(E4:F4) -> 9091548 | I4: 45993 | J4: tiền điện | K4: 6163944 | L4: 493116 | M4: =SUM(K4:L4) -> 6657060
C5: 45993 | D5: tiền phòng 702 Patridge Scott Laurence | E5: 3472222 | F5: 277778 | G5: =SUM(E5:F5) -> 3750000 | I5: 45995 | J5: cmc | K5: 22389 | L5: 2239 | M5: =SUM(K5:L5) -> 24628
C6: 46012 | D6: tiền phòng 302 Acharya Aalhad | E6: 277778 | F6: 22222 | G6: =SUM(E6:F6) -> 300000 | I6: 46001 | J6: chống thấm | K6: 48000000 | L6: 3840000 | M6: =SUM(K6:L6) -> 51840000
C7: 46012 | D7: tiền phòng 702 Kai Kluber Uwe Bernhard | E7: 277778 | F7: 22222 | G7: =SUM(E7:F7) -> 300000 | I7: 46002 | J7: tiền nước | K7: 618001 | L7: 33651 | M7: =SUM(K7:L7) -> 651652
C8: 46012 | D8: tiền phòng 602 Telisheva Mariia | E8: 833333 | F8: 66667 | G8: =SUM(E8:F8) -> 900000 | I8: 46002 | J8: tiền rác | K8: 240909 | L8: 19273 | M8: =SUM(K8:L8) -> 260182
C9: 46017 | D9: tiền phòng 801,802 Van Nhat | E9: 2407407 | F9: 192593 | G9: =SUM(E9:F9) -> 2600000 | I9: 46021 | J9: Agoda | K9: 814815 | L9: 65185 | M9: =SUM(K9:L9) -> 880000
C10: 46019 | D10: tiền phòng 801 Trương mến | E10: 1296296 | F10: 103704 | G10: =SUM(E10:F10) -> 1400000 | I10: 46022 | J10: vimo | K10: 323459 | L10: 32346 | M10: =SUM(K10:L10) -> 355805
C11: 46021 | D11: tiền phòng 501,503 seth carey | E11: 3703704 | F11: 296296 | G11: =SUM(E11:F11) -> 4000000 | I11: 46386 | J11: dasani | K11: 916667 | L11: 73333 | M11: =SUM(K11:L11) -> 990000
C12: 46021 | D12: tiền phòng 702 Gornall Bradley | E12: 1666667 | F12: 133333 | G12: =SUM(E12:F12) -> 1800000 | I12: 46362 | J12: rèm cửa | K12: 924000 | L12: 73920 | M12: =SUM(K12:L12) -> 997920
